{
	"cve": {
		"data_type": "CVE",
		"data_format": "MITRE",
		"data_version": "4.0",
		"CVE_data_meta": {
			"ID": "CVE-2020-13328",
			"ASSIGNER": "cve@mitre.org"
		},
		"problemtype": {
			"problemtype_data": [
				{
					"description": []
				}
			]
		},
		"references": {
			"reference_data": [
				{
					"url": "https://gitlab.com/gitlab-org/cves/-/blob/master/2020/CVE-2020-13328.json",
					"name": "https://gitlab.com/gitlab-org/cves/-/blob/master/2020/CVE-2020-13328.json",
					"refsource": "CONFIRM",
					"tags": []
				},
				{
					"url": "https://gitlab.com/gitlab-org/gitlab/-/issues/215640",
					"name": "https://gitlab.com/gitlab-org/gitlab/-/issues/215640",
					"refsource": "MISC",
					"tags": []
				}
			]
		},
		"description": {
			"description_data": [
				{
					"lang": "en",
					"value": "An issue has been discovered in GitLab affecting versions prior to 13.1.2, 13.0.8 and 12.10.13. GitLab was vulnerable to a stored XSS by using the PyPi files API."
				}
			]
		}
	},
	"configurations": {
		"CVE_data_version": "4.0",
		"nodes": []
	},
	"impact": {},
	"publishedDate": "2020-09-30T18:15Z",
	"lastModifiedDate": "2020-09-30T18:19Z"
}