{
	"cve": {
		"data_type": "CVE",
		"data_format": "MITRE",
		"data_version": "4.0",
		"CVE_data_meta": {
			"ID": "CVE-2022-23564",
			"ASSIGNER": "security-advisories@github.com"
		},
		"problemtype": {
			"problemtype_data": [
				{
					"description": [
						{
							"lang": "en",
							"value": "CWE-617"
						}
					]
				}
			]
		},
		"references": {
			"reference_data": [
				{
					"url": "https://github.com/tensorflow/tensorflow/commit/14fea662350e7c26eb5fe1be2ac31704e5682ee6",
					"name": "https://github.com/tensorflow/tensorflow/commit/14fea662350e7c26eb5fe1be2ac31704e5682ee6",
					"refsource": "MISC",
					"tags": []
				},
				{
					"url": "https://github.com/tensorflow/tensorflow/security/advisories/GHSA-8rcj-c8pj-v3m3",
					"name": "https://github.com/tensorflow/tensorflow/security/advisories/GHSA-8rcj-c8pj-v3m3",
					"refsource": "CONFIRM",
					"tags": []
				}
			]
		},
		"description": {
			"description_data": [
				{
					"lang": "en",
					"value": "Tensorflow is an Open Source Machine Learning Framework. When decoding a resource handle tensor from protobuf, a TensorFlow process can encounter cases where a `CHECK` assertion is invalidated based on user controlled arguments. This allows attackers to cause denial of services in TensorFlow processes. The fix will be included in TensorFlow 2.8.0. We will also cherrypick this commit on TensorFlow 2.7.1, TensorFlow 2.6.3, and TensorFlow 2.5.3, as these are also affected and still in supported range."
				}
			]
		}
	},
	"configurations": {
		"CVE_data_version": "4.0",
		"nodes": []
	},
	"impact": {},
	"publishedDate": "2022-02-04T23:15Z",
	"lastModifiedDate": "2022-02-04T23:28Z"
}