{
	"cve": {
		"data_type": "CVE",
		"data_format": "MITRE",
		"data_version": "4.0",
		"CVE_data_meta": {
			"ID": "CVE-2022-0924",
			"ASSIGNER": "cve@gitlab.com"
		},
		"problemtype": {
			"problemtype_data": [
				{
					"description": []
				}
			]
		},
		"references": {
			"reference_data": [
				{
					"url": "https://gitlab.com/libtiff/libtiff/-/merge_requests/311",
					"name": "https://gitlab.com/libtiff/libtiff/-/merge_requests/311",
					"refsource": "MISC",
					"tags": []
				},
				{
					"url": "https://gitlab.com/gitlab-org/cves/-/blob/master/2022/CVE-2022-0924.json",
					"name": "https://gitlab.com/gitlab-org/cves/-/blob/master/2022/CVE-2022-0924.json",
					"refsource": "CONFIRM",
					"tags": []
				},
				{
					"url": "https://gitlab.com/libtiff/libtiff/-/issues/278",
					"name": "https://gitlab.com/libtiff/libtiff/-/issues/278",
					"refsource": "MISC",
					"tags": []
				}
			]
		},
		"description": {
			"description_data": [
				{
					"lang": "en",
					"value": "Out-of-bounds Read error in tiffcp in libtiff 4.3.0 allows attackers to cause a denial-of-service via a crafted tiff file. For users that compile libtiff from sources, the fix is available with commit 408976c4."
				}
			]
		}
	},
	"configurations": {
		"CVE_data_version": "4.0",
		"nodes": []
	},
	"impact": {},
	"publishedDate": "2022-03-11T18:15Z",
	"lastModifiedDate": "2022-03-11T18:15Z"
}