{
	"cve": {
		"data_type": "CVE",
		"data_format": "MITRE",
		"data_version": "4.0",
		"CVE_data_meta": {
			"ID": "CVE-2021-20275",
			"ASSIGNER": "cve@mitre.org"
		},
		"problemtype": {
			"problemtype_data": [
				{
					"description": [
						{
							"lang": "en",
							"value": "CWE-119"
						}
					]
				}
			]
		},
		"references": {
			"reference_data": [
				{
					"url": "https://bugzilla.redhat.com/show_bug.cgi?id=1936666",
					"name": "https://bugzilla.redhat.com/show_bug.cgi?id=1936666",
					"refsource": "MISC",
					"tags": []
				},
				{
					"url": "https://lists.debian.org/debian-lts-announce/2021/03/msg00009.html",
					"name": "[debian-lts-announce] 20210309 [SECURITY] [DLA 2587-1] privoxy security update",
					"refsource": "MLIST",
					"tags": []
				},
				{
					"url": "https://www.privoxy.org/announce.txt",
					"name": "https://www.privoxy.org/announce.txt",
					"refsource": "MISC",
					"tags": []
				}
			]
		},
		"description": {
			"description_data": [
				{
					"lang": "en",
					"value": "A flaw was found in privoxy before 3.0.32. A invalid read of size two may occur in chunked_body_is_complete() leading to denial of service."
				}
			]
		}
	},
	"configurations": {
		"CVE_data_version": "4.0",
		"nodes": []
	},
	"impact": {},
	"publishedDate": "2021-03-09T14:15Z",
	"lastModifiedDate": "2021-03-09T21:15Z"
}