{
	"cve": {
		"data_type": "CVE",
		"data_format": "MITRE",
		"data_version": "4.0",
		"CVE_data_meta": {
			"ID": "CVE-2021-30501",
			"ASSIGNER": "secalert@redhat.com"
		},
		"problemtype": {
			"problemtype_data": [
				{
					"description": []
				}
			]
		},
		"references": {
			"reference_data": [
				{
					"url": "https://bugzilla.redhat.com/show_bug.cgi?id=1948696",
					"name": "https://bugzilla.redhat.com/show_bug.cgi?id=1948696",
					"refsource": "MISC",
					"tags": []
				},
				{
					"url": "https://github.com/upx/upx/issues/486",
					"name": "https://github.com/upx/upx/issues/486",
					"refsource": "MISC",
					"tags": []
				},
				{
					"url": "https://github.com/upx/upx/pull/487",
					"name": "https://github.com/upx/upx/pull/487",
					"refsource": "MISC",
					"tags": []
				},
				{
					"url": "https://github.com/upx/upx/commit/28e761cd42211dfe0124b7a29b2f74730f453e46",
					"name": "https://github.com/upx/upx/commit/28e761cd42211dfe0124b7a29b2f74730f453e46",
					"refsource": "MISC",
					"tags": []
				}
			]
		},
		"description": {
			"description_data": [
				{
					"lang": "en",
					"value": "An assertion abort was found in upx MemBuffer::alloc() in mem.cpp, in version UPX 4.0.0. The flow allows attackers to cause a denial of service (abort) via a crafted file."
				}
			]
		}
	},
	"configurations": {
		"CVE_data_version": "4.0",
		"nodes": []
	},
	"impact": {},
	"publishedDate": "2021-05-27T00:15Z",
	"lastModifiedDate": "2021-05-27T00:15Z"
}