{
	"cve": {
		"data_type": "CVE",
		"data_format": "MITRE",
		"data_version": "4.0",
		"CVE_data_meta": {
			"ID": "CVE-2020-36242",
			"ASSIGNER": "cve@mitre.org"
		},
		"problemtype": {
			"problemtype_data": [
				{
					"description": []
				}
			]
		},
		"references": {
			"reference_data": [
				{
					"url": "https://github.com/pyca/cryptography/blob/master/CHANGELOG.rst",
					"name": "https://github.com/pyca/cryptography/blob/master/CHANGELOG.rst",
					"refsource": "CONFIRM",
					"tags": []
				},
				{
					"url": "https://github.com/pyca/cryptography/compare/3.3.1...3.3.2",
					"name": "https://github.com/pyca/cryptography/compare/3.3.1...3.3.2",
					"refsource": "CONFIRM",
					"tags": []
				},
				{
					"url": "https://github.com/pyca/cryptography/issues/5615",
					"name": "https://github.com/pyca/cryptography/issues/5615",
					"refsource": "MISC",
					"tags": []
				}
			]
		},
		"description": {
			"description_data": [
				{
					"lang": "en",
					"value": "In the cryptography package before 3.3.2 for Python, certain sequences of update calls to symmetrically encrypt multi-GB values could result in an integer overflow and buffer overflow, as demonstrated by the Fernet class."
				}
			]
		}
	},
	"configurations": {
		"CVE_data_version": "4.0",
		"nodes": []
	},
	"impact": {},
	"publishedDate": "2021-02-07T20:15Z",
	"lastModifiedDate": "2021-02-08T13:26Z"
}