{
	"cve": {
		"data_type": "CVE",
		"data_format": "MITRE",
		"data_version": "4.0",
		"CVE_data_meta": {
			"ID": "CVE-2021-31542",
			"ASSIGNER": "cve@mitre.org"
		},
		"problemtype": {
			"problemtype_data": [
				{
					"description": []
				}
			]
		},
		"references": {
			"reference_data": [
				{
					"url": "https://www.djangoproject.com/weblog/2021/may/04/security-releases/",
					"name": "https://www.djangoproject.com/weblog/2021/may/04/security-releases/",
					"refsource": "MISC",
					"tags": []
				},
				{
					"url": "https://docs.djangoproject.com/en/3.2/releases/security/",
					"name": "https://docs.djangoproject.com/en/3.2/releases/security/",
					"refsource": "MISC",
					"tags": []
				},
				{
					"url": "http://www.openwall.com/lists/oss-security/2021/05/04/3",
					"name": "http://www.openwall.com/lists/oss-security/2021/05/04/3",
					"refsource": "MISC",
					"tags": []
				},
				{
					"url": "https://groups.google.com/forum/#!forum/django-announce",
					"name": "https://groups.google.com/forum/#!forum/django-announce",
					"refsource": "MISC",
					"tags": []
				},
				{
					"url": "https://lists.debian.org/debian-lts-announce/2021/05/msg00005.html",
					"name": "[debian-lts-announce] 20210506 [SECURITY] [DLA 2651-1] python-django security update",
					"refsource": "MLIST",
					"tags": []
				}
			]
		},
		"description": {
			"description_data": [
				{
					"lang": "en",
					"value": "In Django 2.2 before 2.2.21, 3.1 before 3.1.9, and 3.2 before 3.2.1, MultiPartParser, UploadedFile, and FieldFile allowed directory traversal via uploaded files with suitably crafted file names."
				}
			]
		}
	},
	"configurations": {
		"CVE_data_version": "4.0",
		"nodes": []
	},
	"impact": {},
	"publishedDate": "2021-05-05T15:15Z",
	"lastModifiedDate": "2021-05-06T14:15Z"
}